<?xml version='1.0'?>

<robot name="myrobot" xmlns:xacro="http://www.ros.org/wiki/xacro">

<xacro:property name="cameraSize" value="0.05"/>
<xacro:property name="cameraMass" value="0.1"/>


<xacro:include filename="$(find njcrobot_description)/urdf/nmyrobot.gazebo" />
<xacro:include filename="$(find njcrobot_description)/urdf/materials.xacro" />

<link name='chassis'>
   <pose>0 0 1 0 0 0</pose>

   <inertial>
     <mass value="15.0"/>
     <origin xyz="0.0 0 0" rpy=" 0 0 0"/>
     <inertia ixx="1.012625" ixy="0" ixz="0" iyy="1.012625" iyz="0" izz="1.125"/>
   </inertial>

   <collision name='collision'>
     <geometry>
       <box size=".9 .3 .01"/>
     </geometry>
   </collision>

   <visual name='chassis_visual'>
     <origin xyz="0 0 0" rpy=" 0 0 0"/>
     <geometry>
       <box size=".9 .3 .01"/>
     </geometry>
   </visual>

   <visual name='caster_left_frontvisual'>
     <origin xyz="0.4 0.10 -0.05" rpy=" 0 0 0"/>
     <geometry>
       <sphere radius="0.05"/>
     </geometry>
   </visual>

   <collision name='caster_left_frontcollision'>
     <origin xyz="0.4 0.10 -0.05" rpy=" 0 0 0"/>
     <geometry>
       <sphere radius="0.05"/>
     </geometry>
     <surface>
       <friction>
         <ode>
           <mu>0</mu>
           <mu2>0</mu2>
           <slip1>0.1</slip1>
           <slip2>0.1</slip2>
         </ode>
       </friction>
     </surface>
   </collision>

   <visual name='caster_right_frontvisual'>
     <origin xyz="0.4 -0.10 -0.05" rpy=" 0 0 0"/>
     <geometry>
       <sphere radius="0.05"/>
     </geometry>
   </visual>

   <collision name='caster_right_frontcollision'>
     <origin xyz="0.4 -0.10 -0.05" rpy=" 0 0 0"/>
     <geometry>
       <sphere radius="0.05"/>
     </geometry>
     <surface>
       <friction>
         <ode>
           <mu>0</mu>
           <mu2>0</mu2>
           <slip1>0.1</slip1>
           <slip2>0.1</slip2>
         </ode>
       </friction>
     </surface>
   </collision>

   <visual name='caster_left_backvisual'>
     <origin xyz="-0.4 0.10 -0.05" rpy=" 0 0 0"/>
     <geometry>
       <sphere radius="0.05"/>
     </geometry>
   </visual>

   <collision name='caster_left_backcollision'>
     <origin xyz="-0.4 0.10 -0.05" rpy=" 0 0 0"/>
     <geometry>
       <sphere radius="0.05"/>
     </geometry>
     <surface>
       <friction>
         <ode>
           <mu>0</mu>
           <mu2>0</mu2>
           <slip1>0.1</slip1>
           <slip2>0.1</slip2>
         </ode>
       </friction>
     </surface>
   </collision>

   <visual name='caster_right_backvisual'>
     <origin xyz="-0.4 -0.10 -0.05" rpy=" 0 0 0"/>
     <geometry>
       <sphere radius="0.05"/>
     </geometry>
   </visual>

   <collision name='caster_right_backcollision'>
     <origin xyz="-0.4 -0.10 -0.05" rpy=" 0 0 0"/>
     <geometry>
       <sphere radius="0.05"/>
     </geometry>
     <surface>
       <friction>
         <ode>
           <mu>0</mu>
           <mu2>0</mu2>
           <slip1>0.1</slip1>
           <slip2>0.1</slip2>
         </ode>
       </friction>
     </surface>
   </collision>

</link>

<link name="left_wheel">
  <collision name="collision">
    <origin xyz="0 0 0" rpy="0 1.5707 1.5707"/>
    <geometry>
      <cylinder radius="0.1" length="0.025"/>
    </geometry>
  </collision>

   <visual name="left_wheel_visual">
     <origin xyz="0 0 0" rpy="0 1.5707 1.5707"/>
     <geometry>
       <cylinder radius="0.1" length="0.025"/>
     </geometry>
   </visual>

   <inertial>
     <origin xyz="0 0 0" rpy="0 1.5707 1.5707"/>
     <mass value="5"/>
     <inertia ixx="0.02525" ixy="0.0" ixz="0.0" iyy=".02525" iyz="0.0" izz="0.05"/>
   </inertial>

</link>

<link name="right_wheel">
   <visual name="right_wheel_visual">
     <origin xyz="0 0 0" rpy="0 1.5707 1.5707"/>
     <geometry>
       <cylinder radius="0.1" length="0.025"/>
     </geometry>
   </visual>

<collision name="collision">
  <origin xyz="0 0 0" rpy="0 1.5707 1.5707"/>
  <geometry>
    <cylinder radius="0.1" length="0.025"/>
  </geometry>
</collision>

<inertial>
  <origin xyz="0 0 0" rpy="0 1.5707 1.5707"/>
  <mass value="5"/>
  <inertia ixx=".02525" ixy="0.0" ixz="0.0" iyy=".02525" iyz="0.0" izz="0.05"/>
</inertial>

</link>

 <joint type="continuous" name="left_wheel_hinge">
   <origin xyz="-0.0 0.17 0" rpy="0 0 0"/>
   <child link="left_wheel"/>
   <parent link="chassis"/>
   <axis xyz="0 1 0" rpy="0 0 0"/>
   <limit effort="10000" velocity="1000"/>
   <joint_properties damping="0.5" friction="0.5"/>
 </joint>

 <joint type="continuous" name="right_wheel_hinge">
   <origin xyz="0.0 -0.17 0" rpy="0 0 0"/>
   <child link="right_wheel"/>
   <parent link="chassis"/>
   <axis xyz="0 1 0" rpy="0 0 0"/>
   <limit effort="10000" velocity="1000"/>
   <joint_properties damping="0.5" friction="0.5"/>
 </joint>


  <link name="camera">
    <collision>
      <origin xyz="0 0 0" rpy="0 0 0"/>
      <geometry>
        <box size="${cameraSize} ${cameraSize} ${cameraSize}"/>
      </geometry>
    </collision>

    <visual>
      <origin xyz="0 0 0" rpy="0 0 0"/>
      <geometry>
        <box size="${cameraSize} ${cameraSize} ${cameraSize}"/>
      </geometry>
      <material name="green"/>
    </visual>

    <inertial>
      <mass value="${cameraMass}" />
      <origin xyz="0 0 0" rpy="0 0 0"/>
      <box_inertia m="${cameraMass}" x="${cameraSize}" y="${cameraSize}" z="${cameraSize}" />
      <inertia ixx="1e-6" ixy="0" ixz="0" iyy="1e-6" iyz="0" izz="1e-6" />
    </inertial>
  </link>

  <joint name="camera_joint" type="fixed">
    <axis xyz="0 1 0" />
    <origin xyz="0.40 0.050 0.025" rpy="0 0 0"/>
    <parent link="chassis"/>
    <child link="camera"/>
  </joint>


  <joint name="hokuyo_joint" type="fixed">
    <axis xyz="0 1 0" />
    <origin xyz="0.40 0 0.040" rpy="0 0 0"/>
    <parent link="chassis"/>
    <child link="hokuyo"/>
  </joint>

  <!-- Hokuyo Laser -->
  <link name="hokuyo">
    <collision>
      <origin xyz="0 0 0" rpy="0 0 0"/>
      <geometry>
    <box size="0.1 0.1 0.1"/>
      </geometry>
    </collision>

    <visual>
      <origin xyz="0 0 0" rpy="0 0 0"/>
      <geometry>
        <mesh filename="package://njcrobot_description/meshes/hokuyo.dae"/>
      </geometry>
    </visual>

    <inertial>
      <mass value="1e-5" />
      <origin xyz="0 0 0" rpy="0 0 0"/>
      <inertia ixx="1e-6" ixy="0" ixz="0" iyy="1e-6" iyz="0" izz="1e-6" />
    </inertial>
  </link>


<!--link name="arm_link_connector">
<visual>
     <origin rpy="0 0 0 " xyz="0 0 0.102" />
     <geometry>
       <box size="0.05 0.05 0.05"/>
     </geometry>
   </visual>
 </link>

<joint name="arm_link_connector_to_chassis" type="fixed">
   <limit effort="1000.0" lower="-3.14" upper="3.14" velocity="0.2"/>
   <origin rpy"0 0 0" xyz="0 0 0.102"/>
   <parent link="chassis"/>
   <child link="arm_link_connector"/>
 </joint-->


 <!--link name="arm_link_01">
   <visual>
     <origin rpy="0 0 0" xyz="0 0.101 0"/>
     <geometry>
       <cylinder radius="0.017" length="0.08"/>
     </geometry>
   </visual>
</link>

<joint name="arm_link_01_to_arm_link_connector" type="revolute">
   <axis xyz="0 1 0"/>
   <limit effort="1000.0" lower="-3.14" upper="3.14" velocity="0.2"/>
   <origin rpy="0 0 0" xyz="0 0.181 0"/>
   <parent link="arm_link_connector"/>
   <child link="arm_link_01"/>
 </joint>


 <link name="arm_link_02">
   <visual>
     <origin rpy="0 0 0" xyz="0 0.181 0"/>
       <geometry>
         <cylinder radius="0.09" length="0.08"/>
       </geometry>
   </visual>
 </link-->
</robot>
